<?xml version="1.0" ?>
<robot name="spatial_10dof" xmlns:xacro="http://ros.org/wiki/xacro">
    <gazebo>
        <plugin filename="libgazebo_ros_control.so" name="ros_control" />
        <plugin name="gazebo_ros_control" filename="libgazebo_ros_control.so">
            <robotNamespace>/</robotNamespace>
        </plugin>
    </gazebo>
    <link name="base_link">
        <visual>
            <origin xyz="0 0 0" rpy="0 0 0" />
            <geometry>
                <cylinder length="0.01" radius="0.05" />
            </geometry>
            <material name="White">
                <color rgba="1.0 1.0 1.0 1.0" />
            </material>
        </visual>
    </link>
    <link name="link1">
        <visual>
            <origin xyz="0 0 0.05" rpy="0 0 0" />
            <geometry>
                <box size="0.05 0.05 0.1"/>
            </geometry>
            <material name="Blue">
                <color rgba="0.0 0.0 0.8 1.0" />
            </material>
        </visual>
        <collision>
            <origin xyz="0 0 0.05" rpy="0 0 0" />
            <geometry>
                <box size="0.05 0.05 0.1"/>
            </geometry>
        </collision>
        <inertial>
            <mass value="0.1" />
            <origin xyz="0 0 0" rpy="0 0 0" />
            <inertia ixx="0.03" iyy="0.03" izz="0.03" ixy="0.0" ixz="0.0" iyz="0.0" />
        </inertial>
    </link>
    <link name="link2">
        <visual>
            <origin xyz="0 0 0.05" rpy="0 0 0" />
            <geometry>
                <box size="0.05 0.05 0.1"/>
            </geometry>
            <material name="Blue">
                <color rgba="0.0 0.0 0.8 1.0" />
            </material>
        </visual>
        <collision>
            <origin xyz="0 0 0.05" rpy="0 0 0" />
            <geometry>
                <box size="0.05 0.05 0.1"/>
            </geometry>
        </collision>
        <inertial>
            <mass value="0.1" />
            <origin xyz="0 0 0" rpy="0 0 0" />
            <inertia ixx="0.03" iyy="0.03" izz="0.03" ixy="0.0" ixz="0.0" iyz="0.0" />
        </inertial>
    </link>
    <link name="link3">
        <visual>
            <origin xyz="0 0 0.05" rpy="0 0 0" />
            <geometry>
                <box size="0.05 0.05 0.1"/>
            </geometry>
            <material name="Blue">
                <color rgba="0.0 0.0 0.8 1.0" />
            </material>
        </visual>
        <collision>
            <origin xyz="0 0 0.05" rpy="0 0 0" />
            <geometry>
                <box size="0.05 0.05 0.1"/>
            </geometry>
        </collision>
        <inertial>
            <mass value="0.1" />
            <origin xyz="0 0 0" rpy="0 0 0" />
            <inertia ixx="0.03" iyy="0.03" izz="0.03" ixy="0.0" ixz="0.0" iyz="0.0" />
        </inertial>
    </link>
    <link name="link4">
        <visual>
            <origin xyz="0 0 0.05" rpy="0 0 0" />
            <geometry>
                <box size="0.05 0.05 0.1"/>
            </geometry>
            <material name="Blue">
                <color rgba="0.0 0.0 0.8 1.0" />
            </material>
        </visual>
        <collision>
            <origin xyz="0 0 0.05" rpy="0 0 0" />
            <geometry>
                <box size="0.05 0.05 0.1"/>
            </geometry>
        </collision>
        <inertial>
            <mass value="0.1" />
            <origin xyz="0 0 0" rpy="0 0 0" />
            <inertia ixx="0.03" iyy="0.03" izz="0.03" ixy="0.0" ixz="0.0" iyz="0.0" />
        </inertial>
    </link>
    <link name="link5">
        <visual>
            <origin xyz="0 0 0.05" rpy="0 0 0" />
            <geometry>
                <box size="0.05 0.05 0.1"/>
            </geometry>
            <material name="Blue">
                <color rgba="0.0 0.0 0.8 1.0" />
            </material>
        </visual>
        <collision>
            <origin xyz="0 0 0.05" rpy="0 0 0" />
            <geometry>
                <box size="0.05 0.05 0.1"/>
            </geometry>
        </collision>
        <inertial>
            <mass value="0.1" />
            <origin xyz="0 0 0" rpy="0 0 0" />
            <inertia ixx="0.03" iyy="0.03" izz="0.03" ixy="0.0" ixz="0.0" iyz="0.0" />
        </inertial>
    </link>
    <link name="link6">
        <visual>
            <origin xyz="0 0 0.05" rpy="0 0 0" />
            <geometry>
                <box size="0.05 0.05 0.1"/>
            </geometry>
            <material name="Blue">
                <color rgba="0.0 0.0 0.8 1.0" />
            </material>
        </visual>
        <collision>
            <origin xyz="0 0 0.05" rpy="0 0 0" />
            <geometry>
                <box size="0.05 0.05 0.1"/>
            </geometry>
        </collision>
        <inertial>
            <mass value="0.1" />
            <origin xyz="0 0 0" rpy="0 0 0" />
            <inertia ixx="0.03" iyy="0.03" izz="0.03" ixy="0.0" ixz="0.0" iyz="0.0" />
        </inertial>
    </link>
    <link name="link7">
        <visual>
            <origin xyz="0 0 0.05" rpy="0 0 0" />
            <geometry>
                <box size="0.05 0.05 0.1"/>
            </geometry>
            <material name="Blue">
                <color rgba="0.0 0.0 0.8 1.0" />
            </material>
        </visual>
        <collision>
            <origin xyz="0 0 0.05" rpy="0 0 0" />
            <geometry>
                <box size="0.05 0.05 0.1"/>
            </geometry>
        </collision>
        <inertial>
            <mass value="0.1" />
            <origin xyz="0 0 0" rpy="0 0 0" />
            <inertia ixx="0.03" iyy="0.03" izz="0.03" ixy="0.0" ixz="0.0" iyz="0.0" />
        </inertial>
    </link>
    <link name="link8">
        <visual>
            <origin xyz="0 0 0.05" rpy="0 0 0" />
            <geometry>
                <box size="0.05 0.05 0.1"/>
            </geometry>
            <material name="Blue">
                <color rgba="0.0 0.0 0.8 1.0" />
            </material>
        </visual>
        <collision>
            <origin xyz="0 0 0.05" rpy="0 0 0" />
            <geometry>
                <box size="0.05 0.05 0.1"/>
            </geometry>
        </collision>
        <inertial>
            <mass value="0.1" />
            <origin xyz="0 0 0" rpy="0 0 0" />
            <inertia ixx="0.03" iyy="0.03" izz="0.03" ixy="0.0" ixz="0.0" iyz="0.0" />
        </inertial>
    </link>
    <link name="link9">
        <visual>
            <origin xyz="0 0 0.05" rpy="0 0 0" />
            <geometry>
                <box size="0.05 0.05 0.1"/>
            </geometry>
            <material name="Blue">
                <color rgba="0.0 0.0 0.8 1.0" />
            </material>
        </visual>
        <collision>
            <origin xyz="0 0 0.05" rpy="0 0 0" />
            <geometry>
                <box size="0.05 0.05 0.1"/>
            </geometry>
        </collision>
        <inertial>
            <mass value="0.1" />
            <origin xyz="0 0 0" rpy="0 0 0" />
            <inertia ixx="0.03" iyy="0.03" izz="0.03" ixy="0.0" ixz="0.0" iyz="0.0" />
        </inertial>
    </link>
    <link name="link10">
        <visual>
            <origin xyz="0 0 0.05" rpy="0 0 0" />
            <geometry>
                <box size="0.05 0.05 0.1"/>
            </geometry>
            <material name="Blue">
                <color rgba="0.0 0.0 0.8 1.0" />
            </material>
        </visual>
        <collision>
            <origin xyz="0 0 0.05" rpy="0 0 0" />
            <geometry>
                <box size="0.05 0.05 0.1"/>
            </geometry>
        </collision>
        <inertial>
            <mass value="0.1" />
            <origin xyz="0 0 0" rpy="0 0 0" />
            <inertia ixx="0.03" iyy="0.03" izz="0.03" ixy="0.0" ixz="0.0" iyz="0.0" />
        </inertial>
    </link>
    <link name="tool" />
    
    <!-- Joints -->
    <joint name="joint1" type="revolute">
        <limit effort="30" velocity="3.14159" lower="-3.14159" upper="3.14159" />
        <parent link="base_link" />
        <child link="link1" />
        <origin xyz="0 0 0" rpy="0 0 0" />
        <axis xyz="0 0 1" />
    </joint>
    <joint name="joint2" type="revolute">
        <limit effort="30" velocity="3.14159" lower="-3.14159" upper="3.14159" />
        <parent link="link1" />
        <child link="link2" />
        <origin xyz="0 0 0.1" rpy="0 0 0" />
        <axis xyz="1 0 0" />
    </joint>
    <joint name="joint3" type="revolute">
        <limit effort="30" velocity="3.14159" lower="-3.14159" upper="3.14159" />
        <parent link="link2" />
        <child link="link3" />
        <origin xyz="0 0 0.1" rpy="0 0 0" />
        <axis xyz="1 0 0" />
    </joint>
    <joint name="joint4" type="revolute">
        <limit effort="30" velocity="3.14159" lower="-3.14159" upper="3.14159" />
        <parent link="link3" />
        <child link="link4" />
        <origin xyz="0 0 0.1" rpy="0 0 0" />
        <axis xyz="1 0 0" />
    </joint>
    <joint name="joint5" type="revolute">
        <limit effort="30" velocity="3.14159" lower="-3.14159" upper="3.14159" />
        <parent link="link4" />
        <child link="link5" />
        <origin xyz="0 0 0.1" rpy="0 0 0" />
        <axis xyz="1 0 0" />
    </joint>
    <joint name="joint6" type="revolute">
        <limit effort="30" velocity="3.14159" lower="-3.14159" upper="3.14159" />
        <parent link="link5" />
        <child link="link6" />
        <origin xyz="0 0 0.1" rpy="0 0 0" />
        <axis xyz="1 0 0" />
    </joint>
    <joint name="joint7" type="revolute">
        <limit effort="30" velocity="3.14159" lower="-3.14159" upper="3.14159" />
        <parent link="link6" />
        <child link="link7" />
        <origin xyz="0 0 0.1" rpy="0 0 0" />
        <axis xyz="1 0 0" />
    </joint>
    <joint name="joint8" type="revolute">
        <limit effort="30" velocity="3.14159" lower="-3.14159" upper="3.14159" />
        <parent link="link7" />
        <child link="link8" />
        <origin xyz="0 0 0.1" rpy="0 0 0" />
        <axis xyz="1 0 0" />
    </joint>
    <joint name="joint9" type="revolute">
        <limit effort="30" velocity="3.14159" lower="-3.14159" upper="3.14159" />
        <parent link="link8" />
        <child link="link9" />
        <origin xyz="0 0 0.1" rpy="0 0 0" />
        <axis xyz="1 0 0" />
    </joint>
    <joint name="joint10" type="revolute">
        <limit effort="30" velocity="3.14159" lower="-3.14159" upper="3.14159" />
        <parent link="link9" />
        <child link="link10" />
        <origin xyz="0 0 0.1" rpy="0 0 0" />
        <axis xyz="1 0 0" />
    </joint>
    <joint name="ee" type="fixed">
        <parent link="link10" />
        <child link="tool" />
        <limit effort="30" velocity="3.14159" lower="-6.28318" upper="6.28318" />
        <origin xyz="0 0 0.1" rpy="0 0 0" />
        <axis xyz="0 0 1" />
    </joint>
</robot>

